Workbook

Sheet Итоги
A1: «Старт» — итоги финансовой модели для ВТБ
A2: Горизонт: Q1 2027 – Q4 2031 (20 кварталов). Деньги — млн ₽. Значения подтягиваются с листов «Расчёт_П/Б/О»; менять нужно только лист «Допущения».
A4: Показатель | B4: Ед. | C4: Пессимистичный | D4: Базовый | E4: Оптимистичный
A5: Рынок
A6: TAM: молодёжь 14–22 в РФ | B6: тыс. чел. | C6: ='Расчёт_П'!C7 | D6: ='Расчёт_Б'!C7 | E6: ='Расчёт_О'!C7
A7: SAM: с банковской картой | B7: тыс. чел. | C7: ='Расчёт_П'!C8 | D7: ='Расчёт_Б'!C8 | E7: ='Расчёт_О'!C8
A8: SOM: клиенты ВТБ 14–22 | B8: тыс. чел. | C8: ='Расчёт_П'!C9 | D8: ='Расчёт_Б'!C9 | E8: ='Расчёт_О'!C9
A9: Проверка: клиенты ВТБ 14–25 по модели (факт ВТБ — более 4 млн) | B9: тыс. чел. | C9: ='Расчёт_П'!C10 | D9: ='Расчёт_Б'!C10 | E9: ='Расчёт_О'!C10
A10: Дроп-кейсов среди клиентов ВТБ 14–22 в год (без продукта) | B10: шт. | C10: ='Расчёт_П'!C13 | D10: ='Расчёт_Б'!C13 | E10: ='Расчёт_О'!C13
A11: Дроп-кейсов среди клиентов ВТБ 23+ в год (без продукта) | B11: шт. | C11: ='Расчёт_П'!C18 | D11: ='Расчёт_Б'!C18 | E11: ='Расчёт_О'!C18
A12: Экономика клиента
A13: Маржинальный доход на молодого клиента | B13: ₽/год | C13: ='Расчёт_П'!C14 | D13: ='Расчёт_Б'!C14 | E13: ='Расчёт_О'!C14
A14: Затраты банка на один дроп-кейс | B14: ₽ | C14: ='Расчёт_П'!C15 | D14: ='Расчёт_Б'!C15 | E14: ='Расчёт_О'!C15
A15: Инвестиции и затраты
A16: Инвестиции до полного запуска (Q1–Q3 2027) | B16: млн ₽ | C16: ='Расчёт_П'!C77 | D16: ='Расчёт_Б'!C77 | E16: ='Расчёт_О'!C77
A17: Годовые затраты в режиме эксплуатации (2031) | B17: млн ₽ | C17: ='Расчёт_П'!C81 | D17: ='Расчёт_Б'!C81 | E17: ='Расчёт_О'!C81
A18: Суммарные затраты за 5 лет | B18: млн ₽ | C18: ='Расчёт_П'!C75 | D18: ='Расчёт_Б'!C75 | E18: ='Расчёт_О'!C75
A19: Эффект за 5 лет
A20: 1. Экономия на разборе дроп-кейсов молодёжи | B20: млн ₽ | C20: ='Расчёт_П'!AC34 | D20: ='Расчёт_Б'!AC34 | E20: ='Расчёт_О'!AC34
A21: 2. Доход от сохранённых молодых клиентов | B21: млн ₽ | C21: ='Расчёт_П'!AC36 | D21: ='Расчёт_Б'!AC36 | E21: ='Расчёт_О'!AC36
A22: 3. Доход от снижения оттока | B22: млн ₽ | C22: ='Расчёт_П'!AC38 | D22: ='Расчёт_Б'!AC38 | E22: ='Расчёт_О'!AC38
A23: 4. Доход от новых клиентов | B23: млн ₽ | C23: ='Расчёт_П'!AC40 | D23: ='Расчёт_Б'!AC40 | E23: ='Расчёт_О'!AC40
A24: 5. Экономия контакт-центра | B24: млн ₽ | C24: ='Расчёт_П'!AC42 | D24: ='Расчёт_Б'!AC42 | E24: ='Расчёт_О'!AC42
A25: 8. Мост «Детский банк» → «Старт» | B25: млн ₽ | C25: ='Расчёт_П'!AC45 | D25: ='Расчёт_Б'!AC45 | E25: ='Расчёт_О'!AC45
A26: 9. Клиенты из «Пушкинской карты» | B26: млн ₽ | C26: ='Расчёт_П'!AC47 | D26: ='Расчёт_Б'!AC47 | E26: ='Расчёт_О'!AC47
A27: 6. Этап 2: экономия на дроп-кейсах 23+ | B27: млн ₽ | C27: ='Расчёт_П'!AC50 | D27: ='Расчёт_Б'!AC50 | E27: ='Расчёт_О'!AC50
A28: 7. Этап 2: доход от сохранённых взрослых клиентов | B28: млн ₽ | C28: ='Расчёт_П'!AC52 | D28: ='Расчёт_Б'!AC52 | E28: ='Расчёт_О'!AC52
A29: Суммарный эффект за 5 лет | B29: млн ₽ | C29: ='Расчёт_П'!C74 | D29: ='Расчёт_Б'!C74 | E29: ='Расчёт_О'!C74
A30: Годовой эффект (2031) | B30: млн ₽ | C30: ='Расчёт_П'!C82 | D30: ='Расчёт_Б'!C82 | E30: ='Расчёт_О'!C82
A31: Операционный поток 2029 (эффект минус затраты) | B31: млн ₽ | C31: ='Расчёт_П'!C83 | D31: ='Расчёт_Б'!C83 | E31: ='Расчёт_О'!C83
A32: Окупаемость
A33: NPV за 5 лет (2027–2031) | B33: млн ₽ | C33: ='Расчёт_П'!C71 | D33: ='Расчёт_Б'!C71 | E33: ='Расчёт_О'!C71
A34: NPV за 5 лет только ядра продукта | B34: млн ₽ | C34: ='Расчёт_П'!C72 | D34: ='Расчёт_Б'!C72 | E34: ='Расчёт_О'!C72
A35: NPV за первые 3 года (справочно) | B35: млн ₽ | C35: ='Расчёт_П'!C73 | D35: ='Расчёт_Б'!C73 | E35: ='Расчёт_О'!C73
A36: ROI за 5 лет | B36: доля | C36: ='Расчёт_П'!C76 | D36: ='Расчёт_Б'!C76 | E36: ='Расчёт_О'!C76
A37: Срок окупаемости от старта проекта | B37: мес. | C37: ='Расчёт_П'!C79 | D37: ='Расчёт_Б'!C79 | E37: ='Расчёт_О'!C79
A38: Срок окупаемости от полного запуска | B38: мес. | C38: ='Расчёт_П'!C80 | D38: ='Расчёт_Б'!C80 | E38: ='Расчёт_О'!C80
A39: Клиенты и общество (вне NPV)
A40: MAU раздела на конец 2031 | B40: тыс. чел. | C40: ='Расчёт_П'!C87 | D40: ='Расчёт_Б'!C87 | E40: ='Расчёт_О'!C87
A41: Предотвращено дроп-кейсов молодёжи за 5 лет | B41: шт. | C41: ='Расчёт_П'!C84 | D41: ='Расчёт_Б'!C84 | E41: ='Расчёт_О'!C84
...

Sheet Допущения
A1: Допущения финансовой модели «Старт» (антидроп + финграмотность для клиентов 14–22)
A2: Синий шрифт — вводные, их можно менять. Жёлтая заливка — ключевые допущения, которые нужно подтвердить данными ВТБ на пилоте. Чёрный — формулы. Зелёный — ссылки на другие листы.
A4: Допущение | B4: Единица | C4: Пессимистичный | D4: Базовый | E4: Оптимистичный | F4: Источник / обоснование
A6: 1. Рынок и аудитория
A7: Родилось в 2004–2008 гг. (в 2026 им 18–22 года) | B7: тыс. чел. | C7: 7763.5 | D7: 7763.5 | E7: 7763.5 | F7: Росстат, число родившихся по годам: 2004 — 1502,5; 2005 — 1457,4; 2006 — 1479,6; 2007 — 1610,1; 2008 — 1713,9 тыс. Оценка когорты; сверить с численностью населения по возрастам на 01.01.2026 (Росстат).
A8: Родилось в 2009–2012 гг. (в 2026 им 14–17 лет) | B8: тыс. чел. | C8: 7249.3 | D8: 7249.3 | E8: 7249.3 | F8: Росстат: 2009 — 1761,7; 2010 — 1788,9; 2011 — 1796,6; 2012 — 1902,1 тыс.
A9: Коэффициент дожития и миграции когорты | B9: доля | C9: 0.97 | D9: 0.97 | E9: 0.97 | F9: Допущение: смертность в возрасте 0–22 и сальдо миграции. Уточнить по Росстату.
A10: Доля 14–17 лет со своей банковской картой | B10: доля | C10: 0.7 | D10: 0.75 | E10: 0.8 | F10: Допущение. Карта с 14 лет — массовый продукт у всех крупных банков; с лета 2025 нужно согласие родителей.
A11: Доля 18–22 лет с банковской картой | B11: доля | C11: 0.95 | D11: 0.95 | E11: 0.95 | F11: Допущение: стипендии и зарплаты зачисляются на карту, проникновение близко к взрослому.
A12: Доля ВТБ среди 14–17 лет с картой | B12: доля | C12: 0.13 | D12: 0.17 | E12: 0.2 | F12: Калибровка по факту: у ВТБ более 4 млн клиентов 14–25 лет (ВТБ, июнь 2026). Подростков у ВТБ меньше, чем 18–25, поэтому доля 14–17 ≈ 0,6 от доли 18–25. Проверка — строка «клиенты ВТБ 14–25 по модели» на листах расчёта. Пессимистичный сценарий ниже: часть из 4 млн — неактивные клиенты. https://abnews.ru/news/2026/6/1/vtb-zapustit-nakopitelnyj-schet-dlya-molodezhi
A13: Доля ВТБ среди 18–25 лет с картой | B13: доля | C13: 0.22 | D13: 0.28 | E13: 0.32 | F13: Калибровка по факту 4 млн клиентов 14–25 (см. выше). Для сравнения: 30,3 млн активных розничных клиентов ВТБ на конец 2025 г. ≈ четверть банковского населения. https://finance.rambler.ru/business/55672832/
A14: Дропов выявляет ЦБ в месяц (2026) | B14: чел./мес | C14: 40000 | D14: 40000 | E14: 40000 | F14: Б. Шабля (ЦБ), 23.09.2026: ~100 тыс./мес в 2025 → не более 40 тыс./мес в 2026. https://www.interfax.ru/business/1117991 (docs/research/evidence.md № 5)
A15: Доля людей 14–22 лет среди дропов | B15: доля | C15: 0.4 | D15: 0.45 | E15: 0.5 | F15: ЦБ: более 50% базы дропов — моложе 25 лет (А. Афонин, сент. 2026); 14–22 — часть этой группы. Несовершеннолетних среди дроп-счетов 16% (Шабля, I пол. 2026).
A16: Родилось в 2001–2003 гг. (в 2026 им 23–25 лет) — для сверки с фактом ВТБ | B16: тыс. чел. | C16: 4185.8 | D16: 4185.8 | E16: 4185.8 | F16: Росстат: 2001 — 1311,6; 2002 — 1397,0; 2003 — 1477,3 тыс.
A17: Факт: клиентов ВТБ 14–25 лет | B17: тыс. чел. | C17: 4000 | D17: 4000 | E17: 4000 | F17: ВТБ, июнь 2026: «клиентская база банка в возрасте 14–25 лет превышает 4 млн человек». https://abnews.ru/news/2026/6/1/vtb-zapustit-nakopitelnyj-schet-dlya-molodezhi
A19: 2. Экономика молодого клиента
A20: Средние траты по карте молодого клиента | B20: ₽/мес | C20: 10000 | D20: 12000 | E20: 14000 | F20: Допущение (смесь 14–17 и 18–22). Уточнить по данным ВТБ.
A21: Чистый комиссионный доход с оборота (интерчейндж минус расходы и кешбэк) | B21: доля | C21: 0.008 | D21: 0.008 | E21: 0.008 | F21: Допущение: интерчейндж по картам «Мир» ~1–1,5% минус кешбэк и процессинг.
A22: Средний остаток на счетах молодого клиента | B22: ₽ | C22: 6000 | D22: 8000 | E22: 10000 | F22: Допущение. Клиенты 14–25 хранят > 60 млрд ₽ на накопительных счетах ВТБ (июнь 2026).
A23: Процентная маржа на пассивах | B23: доля/год | C23: 0.04 | D23: 0.04 | E23: 0.04 | F23: Допущение: размещение по ставке, близкой к ключевой (14%, ЦБ 11.09.2026), минус ставка по счёту.
A24: Расходы на обслуживание молодого клиента | B24: ₽/год | C24: 400 | D24: 400 | E24: 400 | F24: Допущение: выпуск карты, поддержка, ИТ.
A25: Годовой отток молодых клиентов | B25: доля/год | C25: 0.15 | D25: 0.15 | E25: 0.15 | F25: Допущение. Уточнить по когортам ВТБ.
A27: 3. Затраты банка на один дроп-кейс
A28: Часы антифрод-аналитика на расследование и блокировку | B28: ч | C28: 2 | D28: 2 | E28: 2 | F28: Допущение: разбор операций, блокировка, обмен с ФинЦЕРТ.
A29: Полная стоимость часа аналитика | B29: ₽/ч | C29: 1800 | D29: 1800 | E29: 1800 | F29: Допущение: ~250 тыс. ₽/мес брутто × 1,5 / 165 ч.
A30: Звонков в контакт-центр по одному кейсу | B30: шт. | C30: 3 | D30: 3 | E30: 3 | F30: Допущение: блокировка, разбор, разблокировка.
A31: Стоимость одного звонка в контакт-центр | B31: ₽ | C31: 250 | D31: 250 | E31: 250 | F31: Допущение: ~5 мин × ~50 ₽/мин полной стоимости оператора. Публичных данных банков нет.
A32: Доля кейсов с обжалованием (база ЦБ, жалобы) | B32: доля | C32: 0.5 | D32: 0.5 | E32: 0.5 | F32: Допущение. ЦБ: > 50% заявлений об исключении из базы — от людей моложе 25 лет (evidence.md № 3).
A33: Стоимость обработки обжалования | B33: ₽ | C33: 1500 | D33: 1500 | E33: 1500 | F33: Допущение: ~1 ч специалиста.
A34: Прочие операционные расходы на кейс (отчётность, документы) | B34: ₽ | C34: 500 | D34: 500 | E34: 500 | F34: Допущение.
A35: Доля дроп-кейсов, после которых клиент потерян | B35: доля | C35: 0.7 | D35: 0.7 | E35: 0.7 | F35: Допущение: ограничение ДБО, закрытие счетов, уход клиента.
A36: Чужих денег проходит через один дроп-счёт (для социального эффекта) | B36: ₽ | C36: 150000 | D36: 150000 | E36: 150000 | F36: Оценка: средний чек хищения 18,6 тыс. ₽ (ЦБ, обзор за 2025) × ~8 операций до блокировки. В NPV не входит.
A38: 4. Эффект продукта (гипотезы, проверяем на пилоте)
A39: Доля дроп-кейсов молодёжи, которые остановит перехват перевода + «Безопасный выход» | B39: доля | C39: 0.08 | D39: 0.15 | E39: 0.25 | F39: Гипотеза для A/B-пилота. Перехват работает в переводах у ВСЕХ молодых клиентов, не только у пользователей раздела. На синтетике CatBoost ловит 99% транзитов при 0,9% ложных перехватов (ml/reports/metrics.md), но в жизни часть людей продолжит, а часть схем идёт мимо переводов (передача карты, наличные) — поэтому берём 8–25%.
A40: Дополнительное снижение у активных пользователей раздела (уроки, квест, Щит) | B40: доля | C40: 0.03 | D40: 0.1 | E40: 0.15 | F40: Гипотеза: тот, кто прошёл урок про дропов или проверил сообщение в Щите, реже соглашается на «подработку».
A41: Снижение оттока у пользователей раздела | B41: п.п./год | C41: 0.005 | D41: 0.015 | E41: 0.025 | F41: Гипотеза: регулярное использование раздела (уроки, XP, защита) повышает вовлечённость.
A42: Обращений в КЦ о блокировках и мошенничестве на молодого клиента | B42: шт./год | C42: 0.05 | D42: 0.1 | E42: 0.15 | F42: Допущение. ЦБ: жалоб на отказы и ограничения стало вшестеро больше — 23,8 тыс. за янв.–июль 2026 (evidence.md № 18).
A43: Доля обращений, закрытых самообслуживанием («Безопасный выход», объяснения) | B43: доля | C43: 0.25 | D43: 0.4 | E43: 0.5 | F43: Гипотеза: объяснение причины на экране + пошаговый план без звонка.
A44: Привлечение новых молодых клиентов ВТБ в год (без продукта) | B44: чел./год | C44: 450000 | D44: 450000 | E44: 450000 | F44: Допущение: чтобы база ~2,9 млн не сокращалась при оттоке 15%, банку нужно привлекать ~450 тыс. молодых клиентов в год. ЗАПРОСИТЬ У ВТБ.
A45: Прирост привлечения благодаря продукту | B45: доля | C45: 0.01 | D45: 0.03 | E45: 0.05 | F45: Гипотеза: «банк, который защищает подростка» — аргумент для родителей; партнёрства со школами и вузами.
...

Sheet Расчёт_П
A1: Расчёт: Пессимистичный сценарий
A2: Все значения — формулы от листа «Допущения» (колонка сценария). Деньги — млн ₽.
A4: Аудитория и базовые величины
A5: Молодёжь 14–17 лет в РФ | B5: тыс. чел. | C5: ='Допущения'!$C$8*'Допущения'!$C$9
A6: Молодёжь 18–22 лет в РФ | B6: тыс. чел. | C6: ='Допущения'!$C$7*'Допущения'!$C$9
A7: TAM: вся молодёжь 14–22 | B7: тыс. чел. | C7: =C5+C6
A8: SAM: молодёжь 14–22 с банковской картой | B8: тыс. чел. | C8: =C5*'Допущения'!$C$10+C6*'Допущения'!$C$11
A9: SOM: клиенты ВТБ 14–22 | B9: тыс. чел. | C9: =C5*'Допущения'!$C$10*'Допущения'!$C$12+C6*'Допущения'!$C$11*'Допущения'!$C$13
A10: Проверка: клиенты ВТБ 14–25 по модели (факт ВТБ — на листе «Допущения») | B10: тыс. чел. | C10: =C9+'Допущения'!$C$16*'Допущения'!$C$9*'Допущения'!$C$11*'Допущения'!$C$13
A11: Дропов 14–22 лет в РФ в год | B11: тыс. чел. | C11: ='Допущения'!$C$14*12*'Допущения'!$C$15/1000
A12: Вероятность стать дропом за год для молодого клиента с картой | B12: доля | C12: =IF(C8>0,C11/C8,0)
A13: Дроп-кейсов среди клиентов ВТБ 14–22 в год (без продукта) | B13: шт. | C13: =C9*1000*C12
A14: Маржинальный доход на молодого клиента | B14: ₽/год | C14: ='Допущения'!$C$20*12*'Допущения'!$C$21+'Допущения'!$C$22*'Допущения'!$C$23-'Допущения'!$C$24
A15: Затраты банка на один дроп-кейс | B15: ₽ | C15: ='Допущения'!$C$28*'Допущения'!$C$29+'Допущения'!$C$30*'Допущения'!$C$31+'Допущения'!$C$32*'Допущения'!$C$33+'Допущения'!$C$34
A16: Квартальная ставка дисконтирования | B16: доля | C16: =(1+'Допущения'!$C$81)^(1/4)-1
A17: Полная стоимость сотрудника к зарплате (взносы + накладные) | B17: x | C17: =(1+'Допущения'!$C$76)*(1+'Допущения'!$C$77)
A18: Этап 2: дроп-кейсов среди клиентов ВТБ 23+ в год (без продукта) | B18: шт. | C18: ='Допущения'!$C$14*12*'Допущения'!$C$50*'Допущения'!$C$51
A19: Ценность будущего взрослого клиента на сегодня (на одного молодого клиента) | B19: ₽ | C19: ='Допущения'!$C$57*'Допущения'!$C$53*(1-(1+'Допущения'!$C$81)^(-'Допущения'!$C$59))/'Допущения'!$C$81/(1+'Допущения'!$C$81)^'Допущения'!$C$58
A20: Мост: дополнительно остаются в ВТБ при переходе в 14 лет | B20: чел./год | C20: ='Допущения'!$C$63*'Допущения'!$C$64*'Допущения'!$C$65*'Допущения'!$C$62
A21: Пушкинская карта: новых клиентов через «Старт» | B21: чел./год | C21: ='Допущения'!$C$67*'Допущения'!$C$68*'Допущения'!$C$69*'Допущения'!$C$66
A23: Показатель | B23: Ед. | C23: Q1 2027 | D23: Q2 2027 | E23: Q3 2027 | F23: Q4 2027 | G23: Q1 2028 | H23: Q2 2028 | I23: Q3 2028 | J23: Q4 2028 | K23: Q1 2029 | L23: Q2 2029 | M23: Q3 2029 | N23: Q4 2029 | O23: Q1 2030 | P23: Q2 2030 | Q23: Q3 2030 | R23: Q4 2030 | S23: Q1 2031 | T23: Q2 2031 | U23: Q3 2031 | V23: Q4 2031 | X23: 2027 | Y23: 2028 | Z23: 2029 | AA23: 2030 | AB23: 2031 | AC23: Итого
A24: Номер квартала | B24: № | C24: =1 | D24: =C24+1 | E24: =D24+1 | F24: =E24+1 | G24: =F24+1 | H24: =G24+1 | I24: =H24+1 | J24: =I24+1 | K24: =J24+1 | ... V24: =U24+1
A25: Флаг: разработка и пилот (полная команда) | B25: 0/1 | C25: =IF(C24<='Допущения'!$C$74,1,0) | D25: =IF(D24<='Допущения'!$C$74,1,0) | E25: =IF(E24<='Допущения'!$C$74,1,0) | F25: =IF(F24<='Допущения'!$C$74,1,0) | G25: =IF(G24<='Допущения'!$C$74,1,0) | H25: =IF(H24<='Допущения'!$C$74,1,0) | I25: =IF(I24<='Допущения'!$C$74,1,0) | J25: =IF(J24<='Допущения'!$C$74,1,0) | ... V25: =IF(V24<='Допущения'!$C$74,1,0)
A26: Флаг: продукт запущен для всех | B26: 0/1 | C26: =IF(C24>='Допущения'!$C$75,1,0) | D26: =IF(D24>='Допущения'!$C$75,1,0) | E26: =IF(E24>='Допущения'!$C$75,1,0) | F26: =IF(F24>='Допущения'!$C$75,1,0) | G26: =IF(G24>='Допущения'!$C$75,1,0) | H26: =IF(H24>='Допущения'!$C$75,1,0) | I26: =IF(I24>='Допущения'!$C$75,1,0) | J26: =IF(J24>='Допущения'!$C$75,1,0) | ... V26: =IF(V24>='Допущения'!$C$75,1,0)
A27: Покрытие перехватом (доля молодых клиентов) | B27: доля | C27: ='Допущения'!C$100 | D27: ='Допущения'!D$100 | E27: ='Допущения'!E$100 | F27: ='Допущения'!F$100 | G27: ='Допущения'!G$100 | H27: ='Допущения'!H$100 | I27: ='Допущения'!I$100 | J27: ='Допущения'!J$100 | ... V27: ='Допущения'!V$100 | X27: =F27 | Y27: =J27 | Z27: =N27 | AA27: =R27 | AB27: =V27 | AC27: =V27
A28: Флаг: этап 2 (перехват для клиентов 23+) | B28: 0/1 | C28: =IF(C24>='Допущения'!$C$49,1,0)*'Допущения'!$C$48 | D28: =IF(D24>='Допущения'!$C$49,1,0)*'Допущения'!$C$48 | E28: =IF(E24>='Допущения'!$C$49,1,0)*'Допущения'!$C$48 | F28: =IF(F24>='Допущения'!$C$49,1,0)*'Допущения'!$C$48 | G28: =IF(G24>='Допущения'!$C$49,1,0)*'Допущения'!$C$48 | H28: =IF(H24>='Допущения'!$C$49,1,0)*'Допущения'!$C$48 | I28: =IF(I24>='Допущения'!$C$49,1,0)*'Допущения'!$C$48 | J28: =IF(J24>='Допущения'!$C$49,1,0)*'Допущения'!$C$48 | ... V28: =IF(V24>='Допущения'!$C$49,1,0)*'Допущения'!$C$48
A29: Охват раздела «Старт»
A30: Доля молодых клиентов ВТБ — MAU раздела | B30: доля | C30: =MIN('Допущения'!$C$73,'Допущения'!C$99*'Допущения'!$C$72) | D30: =MIN('Допущения'!$C$73,'Допущения'!D$99*'Допущения'!$C$72) | E30: =MIN('Допущения'!$C$73,'Допущения'!E$99*'Допущения'!$C$72) | F30: =MIN('Допущения'!$C$73,'Допущения'!F$99*'Допущения'!$C$72) | G30: =MIN('Допущения'!$C$73,'Допущения'!G$99*'Допущения'!$C$72) | H30: =MIN('Допущения'!$C$73,'Допущения'!H$99*'Допущения'!$C$72) | I30: =MIN('Допущения'!$C$73,'Допущения'!I$99*'Допущения'!$C$72) | J30: =MIN('Допущения'!$C$73,'Допущения'!J$99*'Допущения'!$C$72) | ... V30: =MIN('Допущения'!$C$73,'Допущения'!V$99*'Допущения'!$C$72) | X30: =F30 | Y30: =J30 | Z30: =N30 | AA30: =R30 | AB30: =V30 | AC30: =V30
A31: MAU раздела «Старт» | B31: тыс. чел. | C31: =$C$9*C30 | D31: =$C$9*D30 | E31: =$C$9*E30 | F31: =$C$9*F30 | G31: =$C$9*G30 | H31: =$C$9*H30 | I31: =$C$9*I30 | J31: =$C$9*J30 | ... V31: =$C$9*V30 | X31: =F31 | Y31: =J31 | Z31: =N31 | AA31: =R31 | AB31: =V31 | AC31: =V31
A32: Эффект для банка — молодёжь 14–22
A33: Предотвращённые дроп-кейсы (перехват у всех + уроки у MAU) | B33: шт. | C33: =$C$9*1000*$C$12/4*(C27*'Допущения'!$C$39+C30*'Допущения'!$C$40) | D33: =$C$9*1000*$C$12/4*(D27*'Допущения'!$C$39+D30*'Допущения'!$C$40) | E33: =$C$9*1000*$C$12/4*(E27*'Допущения'!$C$39+E30*'Допущения'!$C$40) | F33: =$C$9*1000*$C$12/4*(F27*'Допущения'!$C$39+F30*'Допущения'!$C$40) | G33: =$C$9*1000*$C$12/4*(G27*'Допущения'!$C$39+G30*'Допущения'!$C$40) | H33: =$C$9*1000*$C$12/4*(H27*'Допущения'!$C$39+H30*'Допущения'!$C$40) | I33: =$C$9*1000*$C$12/4*(I27*'Допущения'!$C$39+I30*'Допущения'!$C$40) | J33: =$C$9*1000*$C$12/4*(J27*'Допущения'!$C$39+J30*'Допущения'!$C$40) | ... V33: =$C$9*1000*$C$12/4*(V27*'Допущения'!$C$39+V30*'Допущения'!$C$40) | X33: =SUM(C33:F33) | Y33: =SUM(G33:J33) | Z33: =SUM(K33:N33) | AA33: =SUM(O33:R33) | AB33: =SUM(S33:V33) | AC33: =SUM(C33:V33)
A34: 1. Экономия на разборе дроп-кейсов | B34: млн ₽ | C34: =C33*$C$15/1000000 | D34: =D33*$C$15/1000000 | E34: =E33*$C$15/1000000 | F34: =F33*$C$15/1000000 | G34: =G33*$C$15/1000000 | H34: =H33*$C$15/1000000 | I34: =I33*$C$15/1000000 | J34: =J33*$C$15/1000000 | ... V34: =V33*$C$15/1000000 | X34: =SUM(C34:F34) | Y34: =SUM(G34:J34) | Z34: =SUM(K34:N34) | AA34: =SUM(O34:R34) | AB34: =SUM(S34:V34) | AC34: =SUM(C34:V34)
A35: Сохранённые клиенты (не потеряны из-за дропа), накопительно | B35: чел. | C35: =C33*'Допущения'!$C$35 | D35: =C35*(1-'Допущения'!$C$25/4)+D33*'Допущения'!$C$35 | E35: =D35*(1-'Допущения'!$C$25/4)+E33*'Допущения'!$C$35 | F35: =E35*(1-'Допущения'!$C$25/4)+F33*'Допущения'!$C$35 | G35: =F35*(1-'Допущения'!$C$25/4)+G33*'Допущения'!$C$35 | H35: =G35*(1-'Допущения'!$C$25/4)+H33*'Допущения'!$C$35 | I35: =H35*(1-'Допущения'!$C$25/4)+I33*'Допущения'!$C$35 | J35: =I35*(1-'Допущения'!$C$25/4)+J33*'Допущения'!$C$35 | K35: =J35*(1-'Допущения'!$C$25/4)+K33*'Допущения'!$C$35 | ... V35: =U35*(1-'Допущения'!$C$25/4)+V33*'Допущения'!$C$35 | X35: =F35 | Y35: =J35 | Z35: =N35 | AA35: =R35 | AB35: =V35 | AC35: =V35
A36: 2. Доход от сохранённых клиентов | B36: млн ₽ | C36: =C35*$C$14/4/1000000 | D36: =D35*$C$14/4/1000000 | E36: =E35*$C$14/4/1000000 | F36: =F35*$C$14/4/1000000 | G36: =G35*$C$14/4/1000000 | H36: =H35*$C$14/4/1000000 | I36: =I35*$C$14/4/1000000 | J36: =J35*$C$14/4/1000000 | ... V36: =V35*$C$14/4/1000000 | X36: =SUM(C36:F36) | Y36: =SUM(G36:J36) | Z36: =SUM(K36:N36) | AA36: =SUM(O36:R36) | AB36: =SUM(S36:V36) | AC36: =SUM(C36:V36)
A37: Дополнительно удержанные пользователи раздела, накопительно | B37: чел. | C37: =C31*1000*'Допущения'!$C$41/4 | D37: =C37*(1-'Допущения'!$C$25/4)+D31*1000*'Допущения'!$C$41/4 | E37: =D37*(1-'Допущения'!$C$25/4)+E31*1000*'Допущения'!$C$41/4 | F37: =E37*(1-'Допущения'!$C$25/4)+F31*1000*'Допущения'!$C$41/4 | G37: =F37*(1-'Допущения'!$C$25/4)+G31*1000*'Допущения'!$C$41/4 | H37: =G37*(1-'Допущения'!$C$25/4)+H31*1000*'Допущения'!$C$41/4 | I37: =H37*(1-'Допущения'!$C$25/4)+I31*1000*'Допущения'!$C$41/4 | J37: =I37*(1-'Допущения'!$C$25/4)+J31*1000*'Допущения'!$C$41/4 | K37: =J37*(1-'Допущения'!$C$25/4)+K31*1000*'Допущения'!$C$41/4 | ... V37: =U37*(1-'Допущения'!$C$25/4)+V31*1000*'Допущения'!$C$41/4 | X37: =F37 | Y37: =J37 | Z37: =N37 | AA37: =R37 | AB37: =V37 | AC37: =V37
A38: 3. Доход от снижения оттока | B38: млн ₽ | C38: =C37*$C$14/4/1000000 | D38: =D37*$C$14/4/1000000 | E38: =E37*$C$14/4/1000000 | F38: =F37*$C$14/4/1000000 | G38: =G37*$C$14/4/1000000 | H38: =H37*$C$14/4/1000000 | I38: =I37*$C$14/4/1000000 | J38: =J37*$C$14/4/1000000 | ... V38: =V37*$C$14/4/1000000 | X38: =SUM(C38:F38) | Y38: =SUM(G38:J38) | Z38: =SUM(K38:N38) | AA38: =SUM(O38:R38) | AB38: =SUM(S38:V38) | AC38: =SUM(C38:V38)
A39: Новые клиенты благодаря продукту, накопительно | B39: чел. | C39: ='Допущения'!$C$44/4*'Допущения'!$C$45*C26 | D39: =C39*(1-'Допущения'!$C$25/4)+'Допущения'!$C$44/4*'Допущения'!$C$45*D26 | E39: =D39*(1-'Допущения'!$C$25/4)+'Допущения'!$C$44/4*'Допущения'!$C$45*E26 | F39: =E39*(1-'Допущения'!$C$25/4)+'Допущения'!$C$44/4*'Допущения'!$C$45*F26 | G39: =F39*(1-'Допущения'!$C$25/4)+'Допущения'!$C$44/4*'Допущения'!$C$45*G26 | H39: =G39*(1-'Допущения'!$C$25/4)+'Допущения'!$C$44/4*'Допущения'!$C$45*H26 | I39: =H39*(1-'Допущения'!$C$25/4)+'Допущения'!$C$44/4*'Допущения'!$C$45*I26 | J39: =I39*(1-'Допущения'!$C$25/4)+'Допущения'!$C$44/4*'Допущения'!$C$45*J26 | K39: =J39*(1-'Допущения'!$C$25/4)+'Допущения'!$C$44/4*'Допущения'!$C$45*K26 | ... V39: =U39*(1-'Допущения'!$C$25/4)+'Допущения'!$C$44/4*'Допущения'!$C$45*V26 | X39: =F39 | Y39: =J39 | Z39: =N39 | AA39: =R39 | AB39: =V39 | AC39: =V39
A40: 4. Доход от новых клиентов | B40: млн ₽ | C40: =C39*$C$14/4/1000000 | D40: =D39*$C$14/4/1000000 | E40: =E39*$C$14/4/1000000 | F40: =F39*$C$14/4/1000000 | G40: =G39*$C$14/4/1000000 | H40: =H39*$C$14/4/1000000 | I40: =I39*$C$14/4/1000000 | J40: =J39*$C$14/4/1000000 | ... V40: =V39*$C$14/4/1000000 | X40: =SUM(C40:F40) | Y40: =SUM(G40:J40) | Z40: =SUM(K40:N40) | AA40: =SUM(O40:R40) | AB40: =SUM(S40:V40) | AC40: =SUM(C40:V40)
A41: Обращения в КЦ, закрытые самообслуживанием | B41: шт. | C41: =$C$9*1000*'Допущения'!$C$42/4*'Допущения'!$C$43*C27 | D41: =$C$9*1000*'Допущения'!$C$42/4*'Допущения'!$C$43*D27 | E41: =$C$9*1000*'Допущения'!$C$42/4*'Допущения'!$C$43*E27 | F41: =$C$9*1000*'Допущения'!$C$42/4*'Допущения'!$C$43*F27 | G41: =$C$9*1000*'Допущения'!$C$42/4*'Допущения'!$C$43*G27 | H41: =$C$9*1000*'Допущения'!$C$42/4*'Допущения'!$C$43*H27 | I41: =$C$9*1000*'Допущения'!$C$42/4*'Допущения'!$C$43*I27 | J41: =$C$9*1000*'Допущения'!$C$42/4*'Допущения'!$C$43*J27 | ... V41: =$C$9*1000*'Допущения'!$C$42/4*'Допущения'!$C$43*V27 | X41: =SUM(C41:F41) | Y41: =SUM(G41:J41) | Z41: =SUM(K41:N41) | AA41: =SUM(O41:R41) | AB41: =SUM(S41:V41) | AC41: =SUM(C41:V41)
A42: 5. Экономия контакт-центра | B42: млн ₽ | C42: =C41*'Допущения'!$C$31/1000000 | D42: =D41*'Допущения'!$C$31/1000000 | E42: =E41*'Допущения'!$C$31/1000000 | F42: =F41*'Допущения'!$C$31/1000000 | G42: =G41*'Допущения'!$C$31/1000000 | H42: =H41*'Допущения'!$C$31/1000000 | I42: =I41*'Допущения'!$C$31/1000000 | J42: =J41*'Допущения'!$C$31/1000000 | ... V42: =V41*'Допущения'!$C$31/1000000 | X42: =SUM(C42:F42) | Y42: =SUM(G42:J42) | Z42: =SUM(K42:N42) | AA42: =SUM(O42:R42) | AB42: =SUM(S42:V42) | AC42: =SUM(C42:V42)
...

Sheet Расчёт_Б
A1: Расчёт: Базовый сценарий
A2: Все значения — формулы от листа «Допущения» (колонка сценария). Деньги — млн ₽.
A4: Аудитория и базовые величины
A5: Молодёжь 14–17 лет в РФ | B5: тыс. чел. | C5: ='Допущения'!$D$8*'Допущения'!$D$9
A6: Молодёжь 18–22 лет в РФ | B6: тыс. чел. | C6: ='Допущения'!$D$7*'Допущения'!$D$9
A7: TAM: вся молодёжь 14–22 | B7: тыс. чел. | C7: =C5+C6
A8: SAM: молодёжь 14–22 с банковской картой | B8: тыс. чел. | C8: =C5*'Допущения'!$D$10+C6*'Допущения'!$D$11
A9: SOM: клиенты ВТБ 14–22 | B9: тыс. чел. | C9: =C5*'Допущения'!$D$10*'Допущения'!$D$12+C6*'Допущения'!$D$11*'Допущения'!$D$13
A10: Проверка: клиенты ВТБ 14–25 по модели (факт ВТБ — на листе «Допущения») | B10: тыс. чел. | C10: =C9+'Допущения'!$D$16*'Допущения'!$D$9*'Допущения'!$D$11*'Допущения'!$D$13
A11: Дропов 14–22 лет в РФ в год | B11: тыс. чел. | C11: ='Допущения'!$D$14*12*'Допущения'!$D$15/1000
A12: Вероятность стать дропом за год для молодого клиента с картой | B12: доля | C12: =IF(C8>0,C11/C8,0)
A13: Дроп-кейсов среди клиентов ВТБ 14–22 в год (без продукта) | B13: шт. | C13: =C9*1000*C12
A14: Маржинальный доход на молодого клиента | B14: ₽/год | C14: ='Допущения'!$D$20*12*'Допущения'!$D$21+'Допущения'!$D$22*'Допущения'!$D$23-'Допущения'!$D$24
A15: Затраты банка на один дроп-кейс | B15: ₽ | C15: ='Допущения'!$D$28*'Допущения'!$D$29+'Допущения'!$D$30*'Допущения'!$D$31+'Допущения'!$D$32*'Допущения'!$D$33+'Допущения'!$D$34
A16: Квартальная ставка дисконтирования | B16: доля | C16: =(1+'Допущения'!$D$81)^(1/4)-1
A17: Полная стоимость сотрудника к зарплате (взносы + накладные) | B17: x | C17: =(1+'Допущения'!$D$76)*(1+'Допущения'!$D$77)
A18: Этап 2: дроп-кейсов среди клиентов ВТБ 23+ в год (без продукта) | B18: шт. | C18: ='Допущения'!$D$14*12*'Допущения'!$D$50*'Допущения'!$D$51
A19: Ценность будущего взрослого клиента на сегодня (на одного молодого клиента) | B19: ₽ | C19: ='Допущения'!$D$57*'Допущения'!$D$53*(1-(1+'Допущения'!$D$81)^(-'Допущения'!$D$59))/'Допущения'!$D$81/(1+'Допущения'!$D$81)^'Допущения'!$D$58
A20: Мост: дополнительно остаются в ВТБ при переходе в 14 лет | B20: чел./год | C20: ='Допущения'!$D$63*'Допущения'!$D$64*'Допущения'!$D$65*'Допущения'!$D$62
A21: Пушкинская карта: новых клиентов через «Старт» | B21: чел./год | C21: ='Допущения'!$D$67*'Допущения'!$D$68*'Допущения'!$D$69*'Допущения'!$D$66
A23: Показатель | B23: Ед. | C23: Q1 2027 | D23: Q2 2027 | E23: Q3 2027 | F23: Q4 2027 | G23: Q1 2028 | H23: Q2 2028 | I23: Q3 2028 | J23: Q4 2028 | K23: Q1 2029 | L23: Q2 2029 | M23: Q3 2029 | N23: Q4 2029 | O23: Q1 2030 | P23: Q2 2030 | Q23: Q3 2030 | R23: Q4 2030 | S23: Q1 2031 | T23: Q2 2031 | U23: Q3 2031 | V23: Q4 2031 | X23: 2027 | Y23: 2028 | Z23: 2029 | AA23: 2030 | AB23: 2031 | AC23: Итого
A24: Номер квартала | B24: № | C24: =1 | D24: =C24+1 | E24: =D24+1 | F24: =E24+1 | G24: =F24+1 | H24: =G24+1 | I24: =H24+1 | J24: =I24+1 | K24: =J24+1 | ... V24: =U24+1
A25: Флаг: разработка и пилот (полная команда) | B25: 0/1 | C25: =IF(C24<='Допущения'!$D$74,1,0) | D25: =IF(D24<='Допущения'!$D$74,1,0) | E25: =IF(E24<='Допущения'!$D$74,1,0) | F25: =IF(F24<='Допущения'!$D$74,1,0) | G25: =IF(G24<='Допущения'!$D$74,1,0) | H25: =IF(H24<='Допущения'!$D$74,1,0) | I25: =IF(I24<='Допущения'!$D$74,1,0) | J25: =IF(J24<='Допущения'!$D$74,1,0) | ... V25: =IF(V24<='Допущения'!$D$74,1,0)
A26: Флаг: продукт запущен для всех | B26: 0/1 | C26: =IF(C24>='Допущения'!$D$75,1,0) | D26: =IF(D24>='Допущения'!$D$75,1,0) | E26: =IF(E24>='Допущения'!$D$75,1,0) | F26: =IF(F24>='Допущения'!$D$75,1,0) | G26: =IF(G24>='Допущения'!$D$75,1,0) | H26: =IF(H24>='Допущения'!$D$75,1,0) | I26: =IF(I24>='Допущения'!$D$75,1,0) | J26: =IF(J24>='Допущения'!$D$75,1,0) | ... V26: =IF(V24>='Допущения'!$D$75,1,0)
A27: Покрытие перехватом (доля молодых клиентов) | B27: доля | C27: ='Допущения'!C$100 | D27: ='Допущения'!D$100 | E27: ='Допущения'!E$100 | F27: ='Допущения'!F$100 | G27: ='Допущения'!G$100 | H27: ='Допущения'!H$100 | I27: ='Допущения'!I$100 | J27: ='Допущения'!J$100 | ... V27: ='Допущения'!V$100 | X27: =F27 | Y27: =J27 | Z27: =N27 | AA27: =R27 | AB27: =V27 | AC27: =V27
A28: Флаг: этап 2 (перехват для клиентов 23+) | B28: 0/1 | C28: =IF(C24>='Допущения'!$D$49,1,0)*'Допущения'!$D$48 | D28: =IF(D24>='Допущения'!$D$49,1,0)*'Допущения'!$D$48 | E28: =IF(E24>='Допущения'!$D$49,1,0)*'Допущения'!$D$48 | F28: =IF(F24>='Допущения'!$D$49,1,0)*'Допущения'!$D$48 | G28: =IF(G24>='Допущения'!$D$49,1,0)*'Допущения'!$D$48 | H28: =IF(H24>='Допущения'!$D$49,1,0)*'Допущения'!$D$48 | I28: =IF(I24>='Допущения'!$D$49,1,0)*'Допущения'!$D$48 | J28: =IF(J24>='Допущения'!$D$49,1,0)*'Допущения'!$D$48 | ... V28: =IF(V24>='Допущения'!$D$49,1,0)*'Допущения'!$D$48
A29: Охват раздела «Старт»
A30: Доля молодых клиентов ВТБ — MAU раздела | B30: доля | C30: =MIN('Допущения'!$D$73,'Допущения'!C$99*'Допущения'!$D$72) | D30: =MIN('Допущения'!$D$73,'Допущения'!D$99*'Допущения'!$D$72) | E30: =MIN('Допущения'!$D$73,'Допущения'!E$99*'Допущения'!$D$72) | F30: =MIN('Допущения'!$D$73,'Допущения'!F$99*'Допущения'!$D$72) | G30: =MIN('Допущения'!$D$73,'Допущения'!G$99*'Допущения'!$D$72) | H30: =MIN('Допущения'!$D$73,'Допущения'!H$99*'Допущения'!$D$72) | I30: =MIN('Допущения'!$D$73,'Допущения'!I$99*'Допущения'!$D$72) | J30: =MIN('Допущения'!$D$73,'Допущения'!J$99*'Допущения'!$D$72) | ... V30: =MIN('Допущения'!$D$73,'Допущения'!V$99*'Допущения'!$D$72) | X30: =F30 | Y30: =J30 | Z30: =N30 | AA30: =R30 | AB30: =V30 | AC30: =V30
A31: MAU раздела «Старт» | B31: тыс. чел. | C31: =$C$9*C30 | D31: =$C$9*D30 | E31: =$C$9*E30 | F31: =$C$9*F30 | G31: =$C$9*G30 | H31: =$C$9*H30 | I31: =$C$9*I30 | J31: =$C$9*J30 | ... V31: =$C$9*V30 | X31: =F31 | Y31: =J31 | Z31: =N31 | AA31: =R31 | AB31: =V31 | AC31: =V31
A32: Эффект для банка — молодёжь 14–22
A33: Предотвращённые дроп-кейсы (перехват у всех + уроки у MAU) | B33: шт. | C33: =$C$9*1000*$C$12/4*(C27*'Допущения'!$D$39+C30*'Допущения'!$D$40) | D33: =$C$9*1000*$C$12/4*(D27*'Допущения'!$D$39+D30*'Допущения'!$D$40) | E33: =$C$9*1000*$C$12/4*(E27*'Допущения'!$D$39+E30*'Допущения'!$D$40) | F33: =$C$9*1000*$C$12/4*(F27*'Допущения'!$D$39+F30*'Допущения'!$D$40) | G33: =$C$9*1000*$C$12/4*(G27*'Допущения'!$D$39+G30*'Допущения'!$D$40) | H33: =$C$9*1000*$C$12/4*(H27*'Допущения'!$D$39+H30*'Допущения'!$D$40) | I33: =$C$9*1000*$C$12/4*(I27*'Допущения'!$D$39+I30*'Допущения'!$D$40) | J33: =$C$9*1000*$C$12/4*(J27*'Допущения'!$D$39+J30*'Допущения'!$D$40) | ... V33: =$C$9*1000*$C$12/4*(V27*'Допущения'!$D$39+V30*'Допущения'!$D$40) | X33: =SUM(C33:F33) | Y33: =SUM(G33:J33) | Z33: =SUM(K33:N33) | AA33: =SUM(O33:R33) | AB33: =SUM(S33:V33) | AC33: =SUM(C33:V33)
A34: 1. Экономия на разборе дроп-кейсов | B34: млн ₽ | C34: =C33*$C$15/1000000 | D34: =D33*$C$15/1000000 | E34: =E33*$C$15/1000000 | F34: =F33*$C$15/1000000 | G34: =G33*$C$15/1000000 | H34: =H33*$C$15/1000000 | I34: =I33*$C$15/1000000 | J34: =J33*$C$15/1000000 | ... V34: =V33*$C$15/1000000 | X34: =SUM(C34:F34) | Y34: =SUM(G34:J34) | Z34: =SUM(K34:N34) | AA34: =SUM(O34:R34) | AB34: =SUM(S34:V34) | AC34: =SUM(C34:V34)
A35: Сохранённые клиенты (не потеряны из-за дропа), накопительно | B35: чел. | C35: =C33*'Допущения'!$D$35 | D35: =C35*(1-'Допущения'!$D$25/4)+D33*'Допущения'!$D$35 | E35: =D35*(1-'Допущения'!$D$25/4)+E33*'Допущения'!$D$35 | F35: =E35*(1-'Допущения'!$D$25/4)+F33*'Допущения'!$D$35 | G35: =F35*(1-'Допущения'!$D$25/4)+G33*'Допущения'!$D$35 | H35: =G35*(1-'Допущения'!$D$25/4)+H33*'Допущения'!$D$35 | I35: =H35*(1-'Допущения'!$D$25/4)+I33*'Допущения'!$D$35 | J35: =I35*(1-'Допущения'!$D$25/4)+J33*'Допущения'!$D$35 | K35: =J35*(1-'Допущения'!$D$25/4)+K33*'Допущения'!$D$35 | ... V35: =U35*(1-'Допущения'!$D$25/4)+V33*'Допущения'!$D$35 | X35: =F35 | Y35: =J35 | Z35: =N35 | AA35: =R35 | AB35: =V35 | AC35: =V35
A36: 2. Доход от сохранённых клиентов | B36: млн ₽ | C36: =C35*$C$14/4/1000000 | D36: =D35*$C$14/4/1000000 | E36: =E35*$C$14/4/1000000 | F36: =F35*$C$14/4/1000000 | G36: =G35*$C$14/4/1000000 | H36: =H35*$C$14/4/1000000 | I36: =I35*$C$14/4/1000000 | J36: =J35*$C$14/4/1000000 | ... V36: =V35*$C$14/4/1000000 | X36: =SUM(C36:F36) | Y36: =SUM(G36:J36) | Z36: =SUM(K36:N36) | AA36: =SUM(O36:R36) | AB36: =SUM(S36:V36) | AC36: =SUM(C36:V36)
A37: Дополнительно удержанные пользователи раздела, накопительно | B37: чел. | C37: =C31*1000*'Допущения'!$D$41/4 | D37: =C37*(1-'Допущения'!$D$25/4)+D31*1000*'Допущения'!$D$41/4 | E37: =D37*(1-'Допущения'!$D$25/4)+E31*1000*'Допущения'!$D$41/4 | F37: =E37*(1-'Допущения'!$D$25/4)+F31*1000*'Допущения'!$D$41/4 | G37: =F37*(1-'Допущения'!$D$25/4)+G31*1000*'Допущения'!$D$41/4 | H37: =G37*(1-'Допущения'!$D$25/4)+H31*1000*'Допущения'!$D$41/4 | I37: =H37*(1-'Допущения'!$D$25/4)+I31*1000*'Допущения'!$D$41/4 | J37: =I37*(1-'Допущения'!$D$25/4)+J31*1000*'Допущения'!$D$41/4 | K37: =J37*(1-'Допущения'!$D$25/4)+K31*1000*'Допущения'!$D$41/4 | ... V37: =U37*(1-'Допущения'!$D$25/4)+V31*1000*'Допущения'!$D$41/4 | X37: =F37 | Y37: =J37 | Z37: =N37 | AA37: =R37 | AB37: =V37 | AC37: =V37
A38: 3. Доход от снижения оттока | B38: млн ₽ | C38: =C37*$C$14/4/1000000 | D38: =D37*$C$14/4/1000000 | E38: =E37*$C$14/4/1000000 | F38: =F37*$C$14/4/1000000 | G38: =G37*$C$14/4/1000000 | H38: =H37*$C$14/4/1000000 | I38: =I37*$C$14/4/1000000 | J38: =J37*$C$14/4/1000000 | ... V38: =V37*$C$14/4/1000000 | X38: =SUM(C38:F38) | Y38: =SUM(G38:J38) | Z38: =SUM(K38:N38) | AA38: =SUM(O38:R38) | AB38: =SUM(S38:V38) | AC38: =SUM(C38:V38)
A39: Новые клиенты благодаря продукту, накопительно | B39: чел. | C39: ='Допущения'!$D$44/4*'Допущения'!$D$45*C26 | D39: =C39*(1-'Допущения'!$D$25/4)+'Допущения'!$D$44/4*'Допущения'!$D$45*D26 | E39: =D39*(1-'Допущения'!$D$25/4)+'Допущения'!$D$44/4*'Допущения'!$D$45*E26 | F39: =E39*(1-'Допущения'!$D$25/4)+'Допущения'!$D$44/4*'Допущения'!$D$45*F26 | G39: =F39*(1-'Допущения'!$D$25/4)+'Допущения'!$D$44/4*'Допущения'!$D$45*G26 | H39: =G39*(1-'Допущения'!$D$25/4)+'Допущения'!$D$44/4*'Допущения'!$D$45*H26 | I39: =H39*(1-'Допущения'!$D$25/4)+'Допущения'!$D$44/4*'Допущения'!$D$45*I26 | J39: =I39*(1-'Допущения'!$D$25/4)+'Допущения'!$D$44/4*'Допущения'!$D$45*J26 | K39: =J39*(1-'Допущения'!$D$25/4)+'Допущения'!$D$44/4*'Допущения'!$D$45*K26 | ... V39: =U39*(1-'Допущения'!$D$25/4)+'Допущения'!$D$44/4*'Допущения'!$D$45*V26 | X39: =F39 | Y39: =J39 | Z39: =N39 | AA39: =R39 | AB39: =V39 | AC39: =V39
A40: 4. Доход от новых клиентов | B40: млн ₽ | C40: =C39*$C$14/4/1000000 | D40: =D39*$C$14/4/1000000 | E40: =E39*$C$14/4/1000000 | F40: =F39*$C$14/4/1000000 | G40: =G39*$C$14/4/1000000 | H40: =H39*$C$14/4/1000000 | I40: =I39*$C$14/4/1000000 | J40: =J39*$C$14/4/1000000 | ... V40: =V39*$C$14/4/1000000 | X40: =SUM(C40:F40) | Y40: =SUM(G40:J40) | Z40: =SUM(K40:N40) | AA40: =SUM(O40:R40) | AB40: =SUM(S40:V40) | AC40: =SUM(C40:V40)
A41: Обращения в КЦ, закрытые самообслуживанием | B41: шт. | C41: =$C$9*1000*'Допущения'!$D$42/4*'Допущения'!$D$43*C27 | D41: =$C$9*1000*'Допущения'!$D$42/4*'Допущения'!$D$43*D27 | E41: =$C$9*1000*'Допущения'!$D$42/4*'Допущения'!$D$43*E27 | F41: =$C$9*1000*'Допущения'!$D$42/4*'Допущения'!$D$43*F27 | G41: =$C$9*1000*'Допущения'!$D$42/4*'Допущения'!$D$43*G27 | H41: =$C$9*1000*'Допущения'!$D$42/4*'Допущения'!$D$43*H27 | I41: =$C$9*1000*'Допущения'!$D$42/4*'Допущения'!$D$43*I27 | J41: =$C$9*1000*'Допущения'!$D$42/4*'Допущения'!$D$43*J27 | ... V41: =$C$9*1000*'Допущения'!$D$42/4*'Допущения'!$D$43*V27 | X41: =SUM(C41:F41) | Y41: =SUM(G41:J41) | Z41: =SUM(K41:N41) | AA41: =SUM(O41:R41) | AB41: =SUM(S41:V41) | AC41: =SUM(C41:V41)
A42: 5. Экономия контакт-центра | B42: млн ₽ | C42: =C41*'Допущения'!$D$31/1000000 | D42: =D41*'Допущения'!$D$31/1000000 | E42: =E41*'Допущения'!$D$31/1000000 | F42: =F41*'Допущения'!$D$31/1000000 | G42: =G41*'Допущения'!$D$31/1000000 | H42: =H41*'Допущения'!$D$31/1000000 | I42: =I41*'Допущения'!$D$31/1000000 | J42: =J41*'Допущения'!$D$31/1000000 | ... V42: =V41*'Допущения'!$D$31/1000000 | X42: =SUM(C42:F42) | Y42: =SUM(G42:J42) | Z42: =SUM(K42:N42) | AA42: =SUM(O42:R42) | AB42: =SUM(S42:V42) | AC42: =SUM(C42:V42)
...

Sheet Расчёт_О
A1: Расчёт: Оптимистичный сценарий
A2: Все значения — формулы от листа «Допущения» (колонка сценария). Деньги — млн ₽.
A4: Аудитория и базовые величины
A5: Молодёжь 14–17 лет в РФ | B5: тыс. чел. | C5: ='Допущения'!$E$8*'Допущения'!$E$9
A6: Молодёжь 18–22 лет в РФ | B6: тыс. чел. | C6: ='Допущения'!$E$7*'Допущения'!$E$9
A7: TAM: вся молодёжь 14–22 | B7: тыс. чел. | C7: =C5+C6
A8: SAM: молодёжь 14–22 с банковской картой | B8: тыс. чел. | C8: =C5*'Допущения'!$E$10+C6*'Допущения'!$E$11
A9: SOM: клиенты ВТБ 14–22 | B9: тыс. чел. | C9: =C5*'Допущения'!$E$10*'Допущения'!$E$12+C6*'Допущения'!$E$11*'Допущения'!$E$13
A10: Проверка: клиенты ВТБ 14–25 по модели (факт ВТБ — на листе «Допущения») | B10: тыс. чел. | C10: =C9+'Допущения'!$E$16*'Допущения'!$E$9*'Допущения'!$E$11*'Допущения'!$E$13
A11: Дропов 14–22 лет в РФ в год | B11: тыс. чел. | C11: ='Допущения'!$E$14*12*'Допущения'!$E$15/1000
A12: Вероятность стать дропом за год для молодого клиента с картой | B12: доля | C12: =IF(C8>0,C11/C8,0)
A13: Дроп-кейсов среди клиентов ВТБ 14–22 в год (без продукта) | B13: шт. | C13: =C9*1000*C12
A14: Маржинальный доход на молодого клиента | B14: ₽/год | C14: ='Допущения'!$E$20*12*'Допущения'!$E$21+'Допущения'!$E$22*'Допущения'!$E$23-'Допущения'!$E$24
A15: Затраты банка на один дроп-кейс | B15: ₽ | C15: ='Допущения'!$E$28*'Допущения'!$E$29+'Допущения'!$E$30*'Допущения'!$E$31+'Допущения'!$E$32*'Допущения'!$E$33+'Допущения'!$E$34
A16: Квартальная ставка дисконтирования | B16: доля | C16: =(1+'Допущения'!$E$81)^(1/4)-1
A17: Полная стоимость сотрудника к зарплате (взносы + накладные) | B17: x | C17: =(1+'Допущения'!$E$76)*(1+'Допущения'!$E$77)
A18: Этап 2: дроп-кейсов среди клиентов ВТБ 23+ в год (без продукта) | B18: шт. | C18: ='Допущения'!$E$14*12*'Допущения'!$E$50*'Допущения'!$E$51
A19: Ценность будущего взрослого клиента на сегодня (на одного молодого клиента) | B19: ₽ | C19: ='Допущения'!$E$57*'Допущения'!$E$53*(1-(1+'Допущения'!$E$81)^(-'Допущения'!$E$59))/'Допущения'!$E$81/(1+'Допущения'!$E$81)^'Допущения'!$E$58
A20: Мост: дополнительно остаются в ВТБ при переходе в 14 лет | B20: чел./год | C20: ='Допущения'!$E$63*'Допущения'!$E$64*'Допущения'!$E$65*'Допущения'!$E$62
A21: Пушкинская карта: новых клиентов через «Старт» | B21: чел./год | C21: ='Допущения'!$E$67*'Допущения'!$E$68*'Допущения'!$E$69*'Допущения'!$E$66
A23: Показатель | B23: Ед. | C23: Q1 2027 | D23: Q2 2027 | E23: Q3 2027 | F23: Q4 2027 | G23: Q1 2028 | H23: Q2 2028 | I23: Q3 2028 | J23: Q4 2028 | K23: Q1 2029 | L23: Q2 2029 | M23: Q3 2029 | N23: Q4 2029 | O23: Q1 2030 | P23: Q2 2030 | Q23: Q3 2030 | R23: Q4 2030 | S23: Q1 2031 | T23: Q2 2031 | U23: Q3 2031 | V23: Q4 2031 | X23: 2027 | Y23: 2028 | Z23: 2029 | AA23: 2030 | AB23: 2031 | AC23: Итого
A24: Номер квартала | B24: № | C24: =1 | D24: =C24+1 | E24: =D24+1 | F24: =E24+1 | G24: =F24+1 | H24: =G24+1 | I24: =H24+1 | J24: =I24+1 | K24: =J24+1 | ... V24: =U24+1
A25: Флаг: разработка и пилот (полная команда) | B25: 0/1 | C25: =IF(C24<='Допущения'!$E$74,1,0) | D25: =IF(D24<='Допущения'!$E$74,1,0) | E25: =IF(E24<='Допущения'!$E$74,1,0) | F25: =IF(F24<='Допущения'!$E$74,1,0) | G25: =IF(G24<='Допущения'!$E$74,1,0) | H25: =IF(H24<='Допущения'!$E$74,1,0) | I25: =IF(I24<='Допущения'!$E$74,1,0) | J25: =IF(J24<='Допущения'!$E$74,1,0) | ... V25: =IF(V24<='Допущения'!$E$74,1,0)
A26: Флаг: продукт запущен для всех | B26: 0/1 | C26: =IF(C24>='Допущения'!$E$75,1,0) | D26: =IF(D24>='Допущения'!$E$75,1,0) | E26: =IF(E24>='Допущения'!$E$75,1,0) | F26: =IF(F24>='Допущения'!$E$75,1,0) | G26: =IF(G24>='Допущения'!$E$75,1,0) | H26: =IF(H24>='Допущения'!$E$75,1,0) | I26: =IF(I24>='Допущения'!$E$75,1,0) | J26: =IF(J24>='Допущения'!$E$75,1,0) | ... V26: =IF(V24>='Допущения'!$E$75,1,0)
A27: Покрытие перехватом (доля молодых клиентов) | B27: доля | C27: ='Допущения'!C$100 | D27: ='Допущения'!D$100 | E27: ='Допущения'!E$100 | F27: ='Допущения'!F$100 | G27: ='Допущения'!G$100 | H27: ='Допущения'!H$100 | I27: ='Допущения'!I$100 | J27: ='Допущения'!J$100 | ... V27: ='Допущения'!V$100 | X27: =F27 | Y27: =J27 | Z27: =N27 | AA27: =R27 | AB27: =V27 | AC27: =V27
A28: Флаг: этап 2 (перехват для клиентов 23+) | B28: 0/1 | C28: =IF(C24>='Допущения'!$E$49,1,0)*'Допущения'!$E$48 | D28: =IF(D24>='Допущения'!$E$49,1,0)*'Допущения'!$E$48 | E28: =IF(E24>='Допущения'!$E$49,1,0)*'Допущения'!$E$48 | F28: =IF(F24>='Допущения'!$E$49,1,0)*'Допущения'!$E$48 | G28: =IF(G24>='Допущения'!$E$49,1,0)*'Допущения'!$E$48 | H28: =IF(H24>='Допущения'!$E$49,1,0)*'Допущения'!$E$48 | I28: =IF(I24>='Допущения'!$E$49,1,0)*'Допущения'!$E$48 | J28: =IF(J24>='Допущения'!$E$49,1,0)*'Допущения'!$E$48 | ... V28: =IF(V24>='Допущения'!$E$49,1,0)*'Допущения'!$E$48
A29: Охват раздела «Старт»
A30: Доля молодых клиентов ВТБ — MAU раздела | B30: доля | C30: =MIN('Допущения'!$E$73,'Допущения'!C$99*'Допущения'!$E$72) | D30: =MIN('Допущения'!$E$73,'Допущения'!D$99*'Допущения'!$E$72) | E30: =MIN('Допущения'!$E$73,'Допущения'!E$99*'Допущения'!$E$72) | F30: =MIN('Допущения'!$E$73,'Допущения'!F$99*'Допущения'!$E$72) | G30: =MIN('Допущения'!$E$73,'Допущения'!G$99*'Допущения'!$E$72) | H30: =MIN('Допущения'!$E$73,'Допущения'!H$99*'Допущения'!$E$72) | I30: =MIN('Допущения'!$E$73,'Допущения'!I$99*'Допущения'!$E$72) | J30: =MIN('Допущения'!$E$73,'Допущения'!J$99*'Допущения'!$E$72) | ... V30: =MIN('Допущения'!$E$73,'Допущения'!V$99*'Допущения'!$E$72) | X30: =F30 | Y30: =J30 | Z30: =N30 | AA30: =R30 | AB30: =V30 | AC30: =V30
A31: MAU раздела «Старт» | B31: тыс. чел. | C31: =$C$9*C30 | D31: =$C$9*D30 | E31: =$C$9*E30 | F31: =$C$9*F30 | G31: =$C$9*G30 | H31: =$C$9*H30 | I31: =$C$9*I30 | J31: =$C$9*J30 | ... V31: =$C$9*V30 | X31: =F31 | Y31: =J31 | Z31: =N31 | AA31: =R31 | AB31: =V31 | AC31: =V31
A32: Эффект для банка — молодёжь 14–22
A33: Предотвращённые дроп-кейсы (перехват у всех + уроки у MAU) | B33: шт. | C33: =$C$9*1000*$C$12/4*(C27*'Допущения'!$E$39+C30*'Допущения'!$E$40) | D33: =$C$9*1000*$C$12/4*(D27*'Допущения'!$E$39+D30*'Допущения'!$E$40) | E33: =$C$9*1000*$C$12/4*(E27*'Допущения'!$E$39+E30*'Допущения'!$E$40) | F33: =$C$9*1000*$C$12/4*(F27*'Допущения'!$E$39+F30*'Допущения'!$E$40) | G33: =$C$9*1000*$C$12/4*(G27*'Допущения'!$E$39+G30*'Допущения'!$E$40) | H33: =$C$9*1000*$C$12/4*(H27*'Допущения'!$E$39+H30*'Допущения'!$E$40) | I33: =$C$9*1000*$C$12/4*(I27*'Допущения'!$E$39+I30*'Допущения'!$E$40) | J33: =$C$9*1000*$C$12/4*(J27*'Допущения'!$E$39+J30*'Допущения'!$E$40) | ... V33: =$C$9*1000*$C$12/4*(V27*'Допущения'!$E$39+V30*'Допущения'!$E$40) | X33: =SUM(C33:F33) | Y33: =SUM(G33:J33) | Z33: =SUM(K33:N33) | AA33: =SUM(O33:R33) | AB33: =SUM(S33:V33) | AC33: =SUM(C33:V33)
A34: 1. Экономия на разборе дроп-кейсов | B34: млн ₽ | C34: =C33*$C$15/1000000 | D34: =D33*$C$15/1000000 | E34: =E33*$C$15/1000000 | F34: =F33*$C$15/1000000 | G34: =G33*$C$15/1000000 | H34: =H33*$C$15/1000000 | I34: =I33*$C$15/1000000 | J34: =J33*$C$15/1000000 | ... V34: =V33*$C$15/1000000 | X34: =SUM(C34:F34) | Y34: =SUM(G34:J34) | Z34: =SUM(K34:N34) | AA34: =SUM(O34:R34) | AB34: =SUM(S34:V34) | AC34: =SUM(C34:V34)
A35: Сохранённые клиенты (не потеряны из-за дропа), накопительно | B35: чел. | C35: =C33*'Допущения'!$E$35 | D35: =C35*(1-'Допущения'!$E$25/4)+D33*'Допущения'!$E$35 | E35: =D35*(1-'Допущения'!$E$25/4)+E33*'Допущения'!$E$35 | F35: =E35*(1-'Допущения'!$E$25/4)+F33*'Допущения'!$E$35 | G35: =F35*(1-'Допущения'!$E$25/4)+G33*'Допущения'!$E$35 | H35: =G35*(1-'Допущения'!$E$25/4)+H33*'Допущения'!$E$35 | I35: =H35*(1-'Допущения'!$E$25/4)+I33*'Допущения'!$E$35 | J35: =I35*(1-'Допущения'!$E$25/4)+J33*'Допущения'!$E$35 | K35: =J35*(1-'Допущения'!$E$25/4)+K33*'Допущения'!$E$35 | ... V35: =U35*(1-'Допущения'!$E$25/4)+V33*'Допущения'!$E$35 | X35: =F35 | Y35: =J35 | Z35: =N35 | AA35: =R35 | AB35: =V35 | AC35: =V35
A36: 2. Доход от сохранённых клиентов | B36: млн ₽ | C36: =C35*$C$14/4/1000000 | D36: =D35*$C$14/4/1000000 | E36: =E35*$C$14/4/1000000 | F36: =F35*$C$14/4/1000000 | G36: =G35*$C$14/4/1000000 | H36: =H35*$C$14/4/1000000 | I36: =I35*$C$14/4/1000000 | J36: =J35*$C$14/4/1000000 | ... V36: =V35*$C$14/4/1000000 | X36: =SUM(C36:F36) | Y36: =SUM(G36:J36) | Z36: =SUM(K36:N36) | AA36: =SUM(O36:R36) | AB36: =SUM(S36:V36) | AC36: =SUM(C36:V36)
A37: Дополнительно удержанные пользователи раздела, накопительно | B37: чел. | C37: =C31*1000*'Допущения'!$E$41/4 | D37: =C37*(1-'Допущения'!$E$25/4)+D31*1000*'Допущения'!$E$41/4 | E37: =D37*(1-'Допущения'!$E$25/4)+E31*1000*'Допущения'!$E$41/4 | F37: =E37*(1-'Допущения'!$E$25/4)+F31*1000*'Допущения'!$E$41/4 | G37: =F37*(1-'Допущения'!$E$25/4)+G31*1000*'Допущения'!$E$41/4 | H37: =G37*(1-'Допущения'!$E$25/4)+H31*1000*'Допущения'!$E$41/4 | I37: =H37*(1-'Допущения'!$E$25/4)+I31*1000*'Допущения'!$E$41/4 | J37: =I37*(1-'Допущения'!$E$25/4)+J31*1000*'Допущения'!$E$41/4 | K37: =J37*(1-'Допущения'!$E$25/4)+K31*1000*'Допущения'!$E$41/4 | ... V37: =U37*(1-'Допущения'!$E$25/4)+V31*1000*'Допущения'!$E$41/4 | X37: =F37 | Y37: =J37 | Z37: =N37 | AA37: =R37 | AB37: =V37 | AC37: =V37
A38: 3. Доход от снижения оттока | B38: млн ₽ | C38: =C37*$C$14/4/1000000 | D38: =D37*$C$14/4/1000000 | E38: =E37*$C$14/4/1000000 | F38: =F37*$C$14/4/1000000 | G38: =G37*$C$14/4/1000000 | H38: =H37*$C$14/4/1000000 | I38: =I37*$C$14/4/1000000 | J38: =J37*$C$14/4/1000000 | ... V38: =V37*$C$14/4/1000000 | X38: =SUM(C38:F38) | Y38: =SUM(G38:J38) | Z38: =SUM(K38:N38) | AA38: =SUM(O38:R38) | AB38: =SUM(S38:V38) | AC38: =SUM(C38:V38)
A39: Новые клиенты благодаря продукту, накопительно | B39: чел. | C39: ='Допущения'!$E$44/4*'Допущения'!$E$45*C26 | D39: =C39*(1-'Допущения'!$E$25/4)+'Допущения'!$E$44/4*'Допущения'!$E$45*D26 | E39: =D39*(1-'Допущения'!$E$25/4)+'Допущения'!$E$44/4*'Допущения'!$E$45*E26 | F39: =E39*(1-'Допущения'!$E$25/4)+'Допущения'!$E$44/4*'Допущения'!$E$45*F26 | G39: =F39*(1-'Допущения'!$E$25/4)+'Допущения'!$E$44/4*'Допущения'!$E$45*G26 | H39: =G39*(1-'Допущения'!$E$25/4)+'Допущения'!$E$44/4*'Допущения'!$E$45*H26 | I39: =H39*(1-'Допущения'!$E$25/4)+'Допущения'!$E$44/4*'Допущения'!$E$45*I26 | J39: =I39*(1-'Допущения'!$E$25/4)+'Допущения'!$E$44/4*'Допущения'!$E$45*J26 | K39: =J39*(1-'Допущения'!$E$25/4)+'Допущения'!$E$44/4*'Допущения'!$E$45*K26 | ... V39: =U39*(1-'Допущения'!$E$25/4)+'Допущения'!$E$44/4*'Допущения'!$E$45*V26 | X39: =F39 | Y39: =J39 | Z39: =N39 | AA39: =R39 | AB39: =V39 | AC39: =V39
A40: 4. Доход от новых клиентов | B40: млн ₽ | C40: =C39*$C$14/4/1000000 | D40: =D39*$C$14/4/1000000 | E40: =E39*$C$14/4/1000000 | F40: =F39*$C$14/4/1000000 | G40: =G39*$C$14/4/1000000 | H40: =H39*$C$14/4/1000000 | I40: =I39*$C$14/4/1000000 | J40: =J39*$C$14/4/1000000 | ... V40: =V39*$C$14/4/1000000 | X40: =SUM(C40:F40) | Y40: =SUM(G40:J40) | Z40: =SUM(K40:N40) | AA40: =SUM(O40:R40) | AB40: =SUM(S40:V40) | AC40: =SUM(C40:V40)
A41: Обращения в КЦ, закрытые самообслуживанием | B41: шт. | C41: =$C$9*1000*'Допущения'!$E$42/4*'Допущения'!$E$43*C27 | D41: =$C$9*1000*'Допущения'!$E$42/4*'Допущения'!$E$43*D27 | E41: =$C$9*1000*'Допущения'!$E$42/4*'Допущения'!$E$43*E27 | F41: =$C$9*1000*'Допущения'!$E$42/4*'Допущения'!$E$43*F27 | G41: =$C$9*1000*'Допущения'!$E$42/4*'Допущения'!$E$43*G27 | H41: =$C$9*1000*'Допущения'!$E$42/4*'Допущения'!$E$43*H27 | I41: =$C$9*1000*'Допущения'!$E$42/4*'Допущения'!$E$43*I27 | J41: =$C$9*1000*'Допущения'!$E$42/4*'Допущения'!$E$43*J27 | ... V41: =$C$9*1000*'Допущения'!$E$42/4*'Допущения'!$E$43*V27 | X41: =SUM(C41:F41) | Y41: =SUM(G41:J41) | Z41: =SUM(K41:N41) | AA41: =SUM(O41:R41) | AB41: =SUM(S41:V41) | AC41: =SUM(C41:V41)
A42: 5. Экономия контакт-центра | B42: млн ₽ | C42: =C41*'Допущения'!$E$31/1000000 | D42: =D41*'Допущения'!$E$31/1000000 | E42: =E41*'Допущения'!$E$31/1000000 | F42: =F41*'Допущения'!$E$31/1000000 | G42: =G41*'Допущения'!$E$31/1000000 | H42: =H41*'Допущения'!$E$31/1000000 | I42: =I41*'Допущения'!$E$31/1000000 | J42: =J41*'Допущения'!$E$31/1000000 | ... V42: =V41*'Допущения'!$E$31/1000000 | X42: =SUM(C42:F42) | Y42: =SUM(G42:J42) | Z42: =SUM(K42:N42) | AA42: =SUM(O42:R42) | AB42: =SUM(S42:V42) | AC42: =SUM(C42:V42)
...
